Workbook

Sheet Leaderboard
B1: Account Executive Name | C1: Mega Region | D1: Channel | E1: H2'21 NB Quota | F1: H2'21 CO Quota | G1: H2 Total Quota | H1: Tenure based ramp status | I1: Status as of 12/31
B2: Rep1 | C2: APACx | D2: MM | E2: 52500 | F2: 0 | G2: 52500 | H2: Fully ramped | I2: active
B3: Rep2 | C3: MEA | D3: MM | E3: 37994 | F3: 0 | G3: 37994 | H3: Fully ramped | I3: active
B4: Rep3 | C4: MEA | D4: MM | E4: 152587 | F4: 210000 | G4: 362587 | H4: Fully ramped | I4: active
B5: Rep4 | C5: LatAm | D5: SMB | E5: 60000 | F5: 0 | G5: 60000 | H5: Partially ramped | I5: active
B6: Rep5 | C6: APACx | D6: MM | E6: 285319 | F6: 0 | G6: 285319 | H6: Fully ramped | I6: active
B7: Rep6 | C7: APACx | D7: ENT | E7: 189668 | F7: 0 | G7: 189668 | H7: Partially ramped | I7: active
B8: Rep7 | C8: US&Can | D8: SMB | E8: 103950 | F8: 0 | G8: 103950 | H8: Partially ramped | I8: active
B9: Rep8 | C9: LatAm | D9: ENT | E9: 140250 | F9: 0 | G9: 140250 | H9: Partially ramped | I9: active
B10: Rep9 | C10: LatAm | D10: ENT | E10: 115500 | F10: 0 | G10: 115500 | H10: Partially ramped | I10: active
B11: Rep10 | C11: APACx | D11: ENT | E11: 25462 | F11: 0 | G11: 25462 | H11: Partially ramped | I11: active
B12: Rep11 | C12: LatAm | D12: MM | E12: 109725 | F12: 0 | G12: 109725 | H12: Partially ramped | I12: active
B13: Rep12 | C13: APACx | D13: ENT | E13: 189668 | F13: 0 | G13: 189668 | H13: Partially ramped | I13: active
... B186: Rep195 | C186: APACx | D186: ENT | E186: 0 | F186: 0 | G186: 0 | H186: No quota | I186: active

Sheet Attainment Query Data
A1: Unique Dashboard ID | B1: Salesforce Opportunity ID | C1: Salesforce Account ID | D1: Opportunity owner (Account Executive) | E1: Mega region | F1: Channel | G1: Close Date | H1: Product | I1: NB GB (USD) | J1: CO GB (USD) | K1: Total $GB (USD) | L1: Customer Use Case
A2: 0001356c-8549-5751-a23b-0ce25238c4da | B2: 0064z000026LAomAAG | C2: 0014z00001giwevAAA | D2: Rep84 | E2: US&Can | F2: MM | G2: 44536 | H2: eats vouchers | I2: 801.72 | J2: 0 | K2: 801.72 | L2: Eats Vouchers - Recruiting
A3: 000a4a29-6642-4f59-88a5-6b302c1311fd | B3: 0064z000025lMeGAAU | C3: 0014z00001fzJkJAAU | D3: Rep94 | E3: US&Can | F3: ENT | G3: 44474 | H3: eats vouchers | I3: 1632 | J3: 0 | K3: 1632 | L3: Vouchers - Courtesy Meals
A4: 00124a2c-834d-4909-8198-9e6755a2b542 | B4: 0063k00000zHY5pAAG | C4: 0013k00002qQTLzAAO | D4: Rep31 | E4: Europe | F4: MM | G4: 44223 | H4: eats | I4: 0 | J4: 34.84 | K4: 34.84 | L4: eats - Work From Home Meals
A5: 001e2ee0-5b47-403f-a8d6-0740c70c0ebd | B5: 0063k000010YVvAAAW | C5: 0013k00002w922LAAQ | D5: Rep163 | E5: India | F5: ENT | G5: 44291 | H5: central | I5: 0 | J5: 20.71 | K5: 20.71 | L5: Central - Delivery
A6: 001ef1a0-f6d7-568e-b31d-4e56e75a456e | B6: 0064z000026LLkmAAG | C6: 0014z00001hJZEoAAO | D6: Rep186 | E6: US&Can | F6: SMB | G6: 44543 | H6: vouchers | I6: 239.59 | J6: 0 | K6: 239.59 | L6: Rides Vouchers - One-time event transportation
A7: 00372079-d375-5cdb-a137-d2111ea1e2b4 | B7: 0064z000025lFsMAAU | C7: 0014z00001fz1F5AAI | D7: Rep100 | E7: US&Can | F7: ENT | G7: 44517 | H7: eats vouchers | I7: 479.76 | J7: 0 | K7: 479.76 | L7: Eats Vouchers - Employee benefit / reward
A8: 00413e02-ac02-4141-af13-bb65a25d73c2 | B8: 0064z000025ho6mAAA | C8: 0014z00001fHCH9AAO | D8: Rep162 | E8: India | F8: MM | G8: 44473 | H8: travel | I8: 136.23 | J8: 0 | K8: 136.23 | L8: Travel - Business Travel
A9: 00431f67-6716-46da-ba41-daf05ee6894b | B9: 0064z000024lWgSAAU | C9: 0014z00001cWHRKAA4 | D9: Rep162 | E9: India | F9: MM | G9: 44367 | H9: central | I9: 0 | J9: 27.91 | K9: 27.91 | L9: Travel - Business Travel
A10: 00431f67-6716-46da-ba41-daf05ee6894b | B10: 0064z000024lWgSAAU | C10: 0014z00001cWHRKAA4 | D10: Rep162 | E10: India | F10: MM | G10: 44367 | H10: travel | I10: 0 | J10: 353.32 | K10: 353.32 | L10: Travel - Business Travel
A11: 004c3925-a7e2-5558-8b4b-3bec3ee91367 | B11: 0064z000025jYazAAE | C11: 0013k00002jMlxyAAC | D11: Rep23 | E11: US&Can | F11: SMB | G11: 44425 | H11: vouchers | I11: 1252.73 | J11: 0 | K11: 1252.73 | L11: Vouchers - Courtesy Rides
A12: 004c62a8-ab69-405d-8ed9-aad8446e5832 | B12: 0063k00000zHWpEAAW | C12: 0013k00002jMdkKAAS | D12: Rep27 | E12: US&Can | F12: MM | G12: 44440 | H12: eats | I12: 27.65 | J12: 0 | K12: 27.65 | L12: eats - Work From Home Meals
A13: 004cca28-bb39-4118-bab6-f21c18af24b2 | B13: 0063k000010SZEmAAO | C13: 0013k00002t7rxPAAQ | D13: Rep115 | E13: Europe | F13: MM | G13: 44211 | H13: travel | I13: 0 | J13: 42.34 | K13: 42.34 | L13: Travel - Business Travel
... A38: 00d3c6ef-05bd-593e-9273-95f832d6c420 | B38: 0064z000026L1gpAAC | C38: 0014z00001hItWLAA0 | D38: Rep38 | E38: US&Can | F38: SMB | G38: 44538 | H38: travel | I38: 646.32 | J38: 0 | K38: 646.32 | L38: Travel - Business Travel
A39: 00d47f12-ddd3-422a-9149-be3de840ae8c | B39: 0064z000025lANVAA2 | C39: 0013k00002jQ0qNAAS | D39: Rep68 | E39: #N/A | F39: #N/A | G39: 44468 | H39: eats vouchers | I39: 396.43 | J39: 0 | K39: 396.43 | L39: Vouchers - Employee Morale
A40: 00d92a0d-13e5-5cd8-aa6a-4698262eef35 | B40: 0064z000025kCOLAA2 | C40: 0013k00002iUXT0AAO | D40: Rep14 | E40: US&Can | F40: SMB | G40: 44441 | H40: central | I40: 8733.56 | J40: 0 | K40: 8733.56 | L40: Central - Delivery
A41: 00d92a0d-13e5-5cd8-aa6a-4698262eef35 | B41: 0064z000025kCOLAA2 | C41: 0013k00002iUXT0AAO | D41: Rep14 | E41: US&Can | F41: SMB | G41: 44441 | H41: eats vouchers | I41: 691.43 | J41: 0 | K41: 691.43 | L41: Central - Delivery
A42: 00e63c99-78c7-4943-9698-0849978712a0 | B42: 0064z000025hUV1AAM | C42: 0013k00002jQ0hYAAS | D42: Rep47 | E42: US&Can | F42: ENT | G42: 44399 | H42: eats vouchers | I42: 140.19 | J42: 0 | K42: 140.19 | L42: Vouchers - Courtesy Meals
A43: 00fe5137-2936-482e-abab-1eb044d448ff | B43: 0063k000011LSLRAA4 | C43: 0013k00002jNjeSAAS | D43: Rep50 | E43: US&Can | F43: MM | G43: 44330 | H43: central | I43: 0 | J43: 1011.8 | K43: 1011.8 | L43: Travel - Business Travel
A44: 00fe5137-2936-482e-abab-1eb044d448ff | B44: 0063k000011LSLRAA4 | C44: 0013k00002jNjeSAAS | D44: Rep50 | E44: US&Can | F44: MM | G44: 44330 | H44: travel | I44: 0 | J44: 4785.96 | K44: 4785.96 | L44: Travel - Business Travel
A45: 01021b7d-6132-4ed6-a39e-2883cc1bf94a | B45: 0064z000024mmt1AAA | C45: 0013k00002jM19EAAS | D45: Rep36 | E45: US&Can | F45: MM | G45: 44334 | H45: travel | I45: 0 | J45: 3840.16 | K45: 3840.16 | L45: Travel - Commute
A46: 010235fc-2a57-45fc-a45c-e4a8b05c096e | B46: 0064z000025hoX5AAI | C46: 0013k00002jQAsnAAG | D46: Rep36 | E46: US&Can | F46: MM | G46: 44495 | H46: eats vouchers | I46: 4474.98 | J46: 0 | K46: 4474.98 | L46: Vouchers - Incentive / Promotional Tool
A47: 010235fc-2a57-45fc-a45c-e4a8b05c096e | B47: 0064z000025hoX5AAI | C47: 0013k00002jQAsnAAG | D47: Rep36 | E47: US&Can | F47: MM | G47: 44495 | H47: vouchers | I47: 10125.34 | J47: 0 | K47: 10125.34 | L47: Vouchers - Incentive / Promotional Tool
A48: 010bdc58-495a-5170-8dea-ab0058e18dc0 | B48: 0064z000025kbqgAAA | C48: 0014z00001fxIlnAAE | D48: Rep4 | E48: LatAm | F48: SMB | G48: 44452 | H48: travel | I48: 242.85 | J48: 0 | K48: 242.85 | L48: Travel - Business Travel; Travel - Commute
A49: 010bdc58-495a-5170-8dea-ab0058e18dc0 | B49: 0064z000025kbqgAAA | C49: 0014z00001fxIlnAAE | D49: Rep4 | E49: LatAm | F49: SMB | G49: 44452 | H49: vouchers | I49: 182.29 | J49: 0 | K49: 182.29 | L49: Travel - Business Travel; Travel - Commute
A50: 01164f98-bc59-4fdb-b2ad-d702504e8c99 | B50: 0064z000026JD4rAAG | C50: 0013k00002jQ0qKAAS | D50: Rep96 | E50: US&Can | F50: MM | G50: 44489 | H50: eats vouchers | I50: 225.47 | J50: 0 | K50: 225.47 | L50: Vouchers - Courtesy Meals
A51: 011bb750-1461-4460-b0d0-247546ded438 | B51: 0063k000011LxUnAAK | C51: 0013k00002jKxtWAAS | D51: Rep65 | E51: US&Can | F51: MM | G51: 44363 | H51: eats vouchers | I51: 0 | J51: 159.23 | K51: 159.23 | L51: eats - Work From Home Meals
... A56: 01364f92-aca4-4010-94ef-ed83581a7368 | B56: 0064z000025hZi5AAE | C56: 0013k00002lcNgkAAE | D56: Rep117 | E56: MEA | F56: MM | G56: 44378 | H56: travel | I56: 249.99 | J56: 0 | K56: 249.99 | L56: Travel - Business Travel
A57: 013afb3b-cae7-40df-8e2c-e4d497b89a1e | B57: 0063k000010TAxqAAG | C57: 0013k00002jLNWGAA4 | D57: Rep68 | E57: #N/A | F57: #N/A | G57: 44298 | H57: eats vouchers | I57: 0 | J57: 8205.17 | K57: 8205.17 | L57: Vouchers - Courtesy Meals
A58: 013b08d0-d382-4cb7-a45a-818764d44fa8 | B58: 0063k000010YC8ZAAW | C58: 0013k00002iW2baAAC | D58: Rep66 | E58: US&Can | F58: ENT | G58: 44243 | H58: eats vouchers | I58: 0 | J58: 1104.83 | K58: 1104.83 | L58: Vouchers - Courtesy Meals
A59: 013bda93-b809-4ea7-892f-7c43255bc386 | B59: 0064z000025kG3vAAE | C59: 0014z00001fPrQaAAK | D59: Rep23 | E59: US&Can | F59: SMB | G59: 44459 | H59: travel | I59: 134.88 | J59: 0 | K59: 134.88 | L59: Travel - Business Travel
A60: 013cd016-b06a-46d9-9a70-8915ef890879 | B60: 0064z000026K55LAAS | C60: 0013k00002jNSn2AAG | D60: Rep89 | E60: US&Can | F60: MM | G60: 44508 | H60: eats | I60: 67.57 | J60: 0 | K60: 67.57 | L60: Travel - Business Travel; Travel - Commute
A61: 013cd016-b06a-46d9-9a70-8915ef890879 | B61: 0064z000026K55LAAS | C61: 0013k00002jNSn2AAG | D61: Rep89 | E61: US&Can | F61: MM | G61: 44508 | H61: travel | I61: 1742.73 | J61: 0 | K61: 1742.73 | L61: Travel - Business Travel; Travel - Commute
A62: 0145aa52-f0a8-4438-b267-919d6d7372ef | B62: 0064z000024mhStAAI | C62: 0013k00002iWNawAAG | D62: Rep61 | E62: LatAm | F62: MM | G62: 44484 | H62: central | I62: 3907.36 | J62: 0 | K62: 3907.36 | L62: Central - Commute
A63: 0145aa52-f0a8-4438-b267-919d6d7372ef | B63: 0064z000024mhStAAI | C63: 0013k00002iWNawAAG | D63: Rep61 | E63: LatAm | F63: MM | G63: 44484 | H63: travel | I63: 96.37 | J63: 0 | K63: 96.37 | L63: Central - Commute
A64: 014b36b9-0d7f-4eea-aafe-f66e87baeatsa | B64: 0064z000024m2LdAAI | C64: 0014z00001cXRxiAAG | D64: Rep71 | E64: LatAm | F64: MM | G64: 44326 | H64: travel | I64: 0 | J64: 880.87 | K64: 880.87 | L64: Travel - Business Travel
A65: 01579b76-50fb-5309-bf22-9edd68453759 | B65: 0064z000025kfY3AAI | C65: 0013k00002jKoQIAA0 | D65: Rep76 | E65: US&Can | F65: SMB | G65: 44459 | H65: vouchers | I65: 8123.29 | J65: 0 | K65: 8123.29 | L65: Vouchers - Courtesy Rides
A66: 0163be36-7305-4563-8bdc-7404ab0a2dfe | B66: 0064z000025i6lgAAA | C66: 0013k00002jP65CAAS | D66: Rep23 | E66: US&Can | F66: SMB | G66: 44403 | H66: travel | I66: 6299.94 | J66: 0 | K66: 6299.94 | L66: GC - Employee Morale
A67: 0166b862-edc8-4c01-8a0e-0f1102712ada | B67: 0064z000025hm54AAA | C67: 0014z00001eyJJjAAM | D67: Rep1 | E67: APACx | F67: MM | G67: 44389 | H67: eats vouchers | I67: 599.76 | J67: 0 | K67: 599.76 | L67: Vouchers - Employee Morale
A68: 01691228-00ae-45f0-a5d6-c0f5e6a6c9fc | B68: 0064z000024nOSYAA2 | C68: 0013k00002iUXx3AAG | D68: Rep91 | E68: US&Can | F68: MM | G68: 44362 | H68: eats vouchers | I68: 0 | J68: 649.15 | K68: 649.15 | L68: Vouchers - Courtesy Meals
...

Sheet Lookup
B1: Week of 2/18 | C1: Week of 2/25 | D1: Week of 3/3 | E1: Week of 3/10 | F1: Week of 3/17 | G1: Week of 3/24
B2: 43879 | C2: =B2+7 -> 43886 | D2: =C2+7 -> 43893 | E2: =D2+7 -> 43900 | F2: =E2+7 -> 43907 | G2: =F2+7 -> 43914

Sheet Q3 Open Tickets
A1: Timestamp | B1: Email Address | C1: What can we help with? | D1: Which Salesforce Opportunity does this relate to? (please provide link) | E1: Any additional comments? | F1: Notes | G1: Status
A2: 44393.288 | B2: mara.goeckner@uber.com | C2: My New Business Attainment is incorrect | D2: https://u4b.lightning.force.com/lightning/r/Opportunity/0064z000024mn60AAA/view | E2: Gift card opp was not closed. Please change closed won date to July 9 as this is when the gift cards were sent. Thanks! | F2: reflected in attainment | G2: completed
A3: 44393.318 | B3: hooley@uber.com | C3: My Carryover Attainment is incorrect | D3: https://u4b.my.salesforce.com/0064z000024l5wt | E3: Taboola is being pulled into the attainment report for CO meal program, but I've only closed a gift card opp on the account. Is it possible to adjust this? Thank you! | F3: reflected in attainment | G3: completed
A4: 44396.115 | B4: mendes@uber.com | C4: My Carryover Attainment is incorrect | D4: https://u4b.my.salesforce.com/0063k000010YQrD | E4: This account doesn't feature in my carryover attainment. | F4: There are no trips in H2 21 yet. | G4: completed
A5: 44410.681 | B5: francescar@uber.com | C5: My Carryover Attainment is incorrect | D5: https://u4b.lightning.force.com/lightning/r/Opportunity/0064z000024lYvjAAE/view. https://u4b.lightning.force.com/lightning/r/Opportunity/0064z000024lPl4AAE/view. https://u4b.lightning.force.com/lightning/r/Opportunity/0064z000024lPl9AAE/view. https://u4b.lightning.force.com/lightning/r/Opportunity/0064z000024lPlAAAU/view. | E5: Just noticed that 4 of the dashboards I closed in H1 under Virtual Kitchen Co. have different numbers pulling into the attainment report from the actuals. 57bd3703-f9e4-4d51-b766-4404416acedc - $597.77 0507c1b3-4f7d-4fe7-9e33-7859ece1fdb7 - $44,613.72 cd047bc4-7fed-4b59-99b9-3490548335c3 - $17,100.95 3e8dd309-9e06-4e11-956d-27a8973f99b6 - $21,969.97 CO$GB from attainment report: $31,896 Total (granted 7/27 leaves a few days for revenue in July): $84,879.41 | F5: The correct GB is reflected in attainment | G5: completed
A6: 44413.53 | B6: ch.james@uber.com | C6: My New Business Attainment is incorrect | D6: https://u4b.lightning.force.com/lightning/r/Opportunity/0064z000025hp20AAA/view | E6: vouchers NB attainment not populating. CW opp 7.9.2021 | F6: reflected in attainment | G6: completed
A7: 44421.424 | B7: francescar@uber.com | C7: My Carryover Attainment is incorrect | D7: cd047bc4-7fed-4b59-99b9-3490548335c3,3e8dd309-9e06-4e11-956d-27a8973f99b6, 57bd3703-f9e4-4d51-b766-4404416acedc, 0507c1b3-4f7d-4fe7-9e33-7859ece1fdb7, | E7: 7/1 - 8/10 Carryover GB: All Day Kitchen - Rides 0507c1b3-4f7d-4fe7-9e33-7859ece1fdb7 - $49,170.72 All Day Kitchens - cd047bc4-7fed-4b59-99b9-3490548335c3 - $22,143.95 Vrias Foods - Eats - 3e8dd309-9e06-4e11-956d-27a8973f99b6 - $25,013.11 Vrias foods - Rides 57bd3703-f9e4-4d51-b766-4404416acedc - $764.44 Attainment Report: 52,071 Missing = 45,021.22 | F7: reflected in attainment | G7: completed
A8: 44421.502 | B8: danielb@uber.com | C8: My Total Attainment is incorrect | D8: https://u4b.my.salesforce.com/0063k00000ybuo6 | E8: I've not received any attainment for this opportunity this half. Please update. | F8: reflected in attainment | G8: completed
A9: 44432.397 | B9: kiran.rao@uber.com | C9: My Carryover Attainment is incorrect | D9: https://u4b.my.salesforce.com/0064z000024mlAPAAY | E9: The CO GB should have been USD 1691. GB Reflecting in attainment USD 1409 GB Missing USD 282 | F9: reflected in attainment | G9: completed
A10: 44434.774 | B10: gwallworth@uber.com | C10: My New Business Attainment is incorrect | D10: https://u4b.my.salesforce.com/0064z000024nSc3 | E10: Open case #10534392 - sitting with Jassem Shukr regarding the transfer of this opp into my name for attainment. Previously CW vouchers by a rep who is no longer with Uber, approval from Juan to create a new opp as there was low spend on the account and grown to 60K plus GB. SF doesn't allow me to create a new opp for vouchers so the request is for the opp to be transferred to me with attainment from the 20th of Aug onwards. Thankyou | F10: reflected in attainment | G10: completed
A11: 44435.265 | B11: mara.goeckner@uber.com | C11: My New Business Attainment is incorrect | D11: https://u4b.lightning.force.com/lightning/r/Opportunity/0064z000024lb6XAAQ/view?0.source=alohaHeader | E11: There is no GB from this account pulling into the attainment report | F11: reflected in attainment | G11: completed
A12: 44446.791 | B12: kayvanc@uber.com | C12: My New Business Attainment is incorrect | D12: https://u4b.my.salesforce.com/0064z000024lSC9?srPos=0&srKp=006 | E12: UUID: b9048c5f-56a6-450d-8292-7b65ef0e444a Per attainment, H2 spend = $72,521.10 (incorrect) Per the UUID / Dashboard, July 2021 spend = $84,041.93 Please update H2 attainment for this UUID to $84,041.93. It would be great if it could accurately reflect on this upcoming attainment report. Thank you! | G12: completed
A13: 44448.82 | B13: josh.miller@uber.com | C13: My Total Attainment is incorrect | D13: 1) https://u4b.lightning.force.com/lightning/r/Opportunity/0064z000025kCOLAA2/view 2) https://u4b.lightning.force.com/lightning/r/Opportunity/0064z000025jthUAAQ/view 3) https://u4b.lightning.force.com/lightning/r/Opportunity/0064z000025jaQvAAI/view | E13: These opps are closed/won opps using existing UUID’s. These clients indicated they would used Central for delivery. From what I can tell these orgs have unfortunately not started using Connect on Central. I believe this would show the vehicle category as “connect” if so. I want to call these out as I am worried I am being given attainment for courtesy rides I did not initiate. My questions: -Do we need to create a new UUID for delivery to be tracked separately from courtesy rides? -Will these opps be tracked correctly if we create a new program for delivery under the same UUID? -Will these opps track correctly if we submit the product as Central/Delivery on the same program as courtesy rides? My apologies for any mixup here, please advise on how to proceed. Thanks, Josh | G13: completed
A14: 44451.824 | B14: ruby.rios@uber.com | C14: My Total Attainment is incorrect | D14: General Question | E14: Can you clearly define what is included in GB? The reports for the UUIDs in office space do not add up to the attainment report for multiple accounts. It was brought to my attention that tips and taxes are not counted towards our total GB number. Are the tips/taxes not being counted in attainment a new policy? Is there anything else that is not counted in our attainment number? What report can we pull to check and balance the attainment report if not office space? | G14: completed
A15: 44454.604 | B15: mdecastro@uber.com | C15: My Total Attainment is incorrect | D15: Radiant Health Centers | E15: There are several accounts across all health AEs that appear to be showing until travel and health GB. Radiant Health Centers is an example. | F15: reflected in attainment | G15: completed
A16: 44459.306 | B16: gkauffmann@uber.com | C16: My Carryover Attainment is incorrect | D16: https://u4b.lightning.force.com/lightning/r/Opportunity/0063k000010RrGfAAK/view | E16: API Direct Deal closed-won in April/2021 and GB is not being considered (I believe) in my att. Team, could you please, verify? Thanks, | F16: reflected in attainment | G16: completed
A17: 44461.416 | B17: guilherme.gabriel@uber.com | C17: My New Business Attainment is incorrect | D17: Acount 0013k00002jQPveAAG | E17: Could you pls confirm the acct 0013k00002jQPveAAG is spending on connect/flash? We checked on office-space and with the client it does not seems they are spending in this solution? | F17: central/connect was not sold, and it was requested to be removed | G17: completed
A18: 44461.416 | B18: guilherme.gabriel@uber.com | C18: My New Business Attainment is incorrect | D18: Account 0013k00002jLdlsAAC | E18: ccount 0013k00002jLdlsAAC - spend seems much lower than amount observed in office space ($3,246 in attn report vs. ~8k checking office-space) | F18: correctly reflected in attainment | G18: completed
A19: 44461.416 | B19: guilherme.gabriel@uber.com | C19: My New Business Attainment is incorrect | D19: UUID 05520de5-be56-587d-9341-023aa68ddee9 | E19: ASSINO CREDITO IMOBILIARIO: AE did not sell travel UUID 05520de5-be56-587d-9341-023aa68ddee9 Value to be disconsidered $1245 | F19: reflected in attainment | G19: completed
A20: 44461.417 | B20: guilherme.gabriel@uber.com | C20: My New Business Attainment is incorrect | D20: UUID 3eeaa4ee-d16f-4bb7-910c-b48513d56ad3 | E20: COMUNICARE COMERCIO DE APARELHOS AUDITIVOS LTDA AE did not sell travel UUID 3eeaa4ee-d16f-4bb7-910c-b48513d56ad3 Value to be disconsidered $3113 | F20: reflected in attainment | G20: completed
A21: 44461.417 | B21: guilherme.gabriel@uber.com | C21: My New Business Attainment is incorrect | D21: UUID 68232936-8af5-539f-bc95-2d5d09364a4c | E21: Nexcorp ServiÁos e TelecomunicaÁıes S.A. AE did not sell travel UUID 68232936-8af5-539f-bc95-2d5d09364a4c Value to be disconsidered $8043 | F21: reflected in attainment | G21: completed
A22: 44461.417 | B22: guilherme.gabriel@uber.com | C22: My New Business Attainment is incorrect | D22: UUID 850c227f-b953-48fb-866d-4e7477328392 | E22: ALFILM AMAZONIA IND E COM LTDA AE did not sell travel UUID 850c227f-b953-48fb-866d-4e7477328392 Value to be disconsidered $2400 | F22: reflected in attainment | G22: completed
A23: 44461.417 | B23: guilherme.gabriel@uber.com | C23: My New Business Attainment is incorrect | D23: UUID f2748eaa-15c9-458d-9b77-9d0cdccd1e2b | E23: YAMADA-LOM FABRICA????O DE ARTEFATOS DE MATERIAL PL?STICO LTDA. AE did not sell travel UUID f2748eaa-15c9-458d-9b77-9d0cdccd1e2b Value to be disconsidered $456 | F23: reflected in attainment | G23: completed
A24: 44461.417 | B24: guilherme.gabriel@uber.com | C24: My New Business Attainment is incorrect | D24: UUID 96850bad-a924-4fe9-85e5-aec7c890b230 | E24: IKM Servicios Central Central not sold by AE UUID 96850bad-a924-4fe9-85e5-aec7c890b230 Value to be disconsidered $49.37 | F24: reflected in attainment | G24: completed
A25: 44461.418 | B25: guilherme.gabriel@uber.com | C25: My New Business Attainment is incorrect | D25: UUID 96850bad-a924-4fe9-85e5-aec7c890b230 | E25: IKM Servicios Central Travel not sold by AE UUID 96850bad-a924-4fe9-85e5-aec7c890b230 Vaue to be disconsidered $2391.18 | F25: reflected in attainment | G25: completed
A26: 44461.418 | B26: guilherme.gabriel@uber.com | C26: My New Business Attainment is incorrect | D26: UUID cf76249e-74b2-44c3-aff1-c4c451764102 | E26: BCYSA Servicios Industriales SA de CV travel Travel not sold by AE UUID cf76249e-74b2-44c3-aff1-c4c451764102 Vaue to be disconsidered $2010.99 | F26: reflected in attainment | G26: completed
... A62: 44477.526 | B62: guilherme.gabriel@uber.com | C62: My Total Attainment is incorrect | D62: https://u4b.lightning.force.com/lightning/r/Opportunity/0063k00000yYYJFAA4/view | E62: Grupo Loyga SA de CV-2020-01-27 868e347b-f0da-489a-9310-a013dc1d3ac2 Travel was not sold by the AE and should not be considered | F62: reflected in attainment | G62: completed
A63: 44477.547 | B63: stephen.chapman@uber.com | C63: My New Business Attainment is incorrect | D63: https://u4b.my.salesforce.com/0064z000025jcZv?srPos=0&srKp=006 | E63: The UUID on that Opp is incorrect. Can you populate it with the correct UUID included below? 8c870501-d6a1-4658-a944-1e493de7e982
A64: 44477.548 | B64: stephen.chapman@uber.com | C64: My New Business Attainment is incorrect | D64: https://u4b.my.salesforce.com/0064z000025jtsD?srPos=0&srKp=006 | E64: The closed won - Optiver Eats, is not pulling the GB into the attainment. Not sure why, they are spending. UUID: 17044f8a-20af-4333-b9d8-a7ea31382338
A65: 44479.951 | B65: mendes@uber.com | C65: My New Business Attainment is incorrect | D65: https://u4b.lightning.force.com/lightning/r/Opportunity/0064z000025izaQAAQ/view | E65: There is a discrepancy in the GB attributed vs Trips taken.
A66: 44481.323 | B66: michelle.caldas@uber.com | C66: My Carryover Attainment is incorrect | D66: https://u4b.lightning.force.com/lightning/r/Opportunity/0063k000011LKT3AAO/view | E66: The total carryover from July 1 - Sept 30 should be $83,993.77
A67: 44481.338 | B67: michelle.caldas@uber.com | C67: My New Business Attainment is incorrect | D67: https://u4b.lightning.force.com/lightning/r/Opportunity/0064z000025iGasAAE/view | E67: Total new business in vouchers for Q3 should be $2,497.50
A68: 44481.34 | B68: michelle.caldas@uber.com | C68: My New Business Attainment is incorrect | D68: https://u4b.lightning.force.com/lightning/r/Opportunity/0064z000025iVpGAAU/view | E68: New Business GB should be $1,364
A69: 44481.348 | B69: michelle.caldas@uber.com | C69: My New Business Attainment is incorrect | D69: https://u4b.lightning.force.com/lightning/r/Opportunity/0064z000025iW8cAAE/view | E69: New Business total from Sept 1 - 30 should be $153,965
A70: 44481.381 | B70: michelle.caldas@uber.com | C70: My New Business Attainment is incorrect | D70: https://u4b.lightning.force.com/lightning/r/Opportunity/0064z000025hHEtAAM/view | E70: Attainment should be $25,678.53 for Q3
A71: 44481.481 | B71: hooley@uber.com | C71: My New Business Attainment is incorrect | D71: 22fad395-8a5f-4cbc-b62a-02a720eea36f | E71: Travel GB is pulling into NB attainment, but it should only be Eats. Thanks!
A72: 44481.482 | B72: hooley@uber.com | C72: My New Business Attainment is incorrect | D72: 2b2bfd08-bddd-5177-b6fd-b61a1fb4045e | E72: Travel GB is pulling into NB attainment, but only Eats and Vouchers GB should be pulling in. Thanks!
A73: 44481.483 | B73: hooley@uber.com | C73: My New Business Attainment is incorrect | D73: 673aec42-4933-4212-a600-e7eb018c7286 | E73: Travel GB is pulling into NB attainment, but only Eats should be. Thanks!
A74: 44481.483 | B74: hooley@uber.com | C74: My New Business Attainment is incorrect | D74: d00c3236-041d-49dd-96f1-a494ad1729fe | E74: Travel and Vouchers GB is pulling into NB attainment, but only Eats should be. Thanks!
... A76: 44481.488 | B76: bains@uber.com | C76: My New Business Attainment is incorrect | D76: https://u4b.lightning.force.com/lightning/r/Opportunity/0064z000025kbxNAAQ/view | E76: Voucher opportunity not showing at all in NB, closed 9/26
...

Sheet Copy of Total Launches by Produ
D2: 43879 | E2: =D3 -> 43886 | F2: =E3 -> 43893 | G2: =F3 -> 43900 | H2: =G3 -> 43907 | I2: =H3 -> 43914 | J2: =I3 -> 43921 | K2: =J3 -> 43928 | L2: =K3 -> 43935 | ... V2: =U3 -> 44005 | W2: 44013
D3: =D2+7 -> 43886 | E3: =E2+7 -> 43893 | F3: =F2+7 -> 43900 | G3: =G2+7 -> 43907 | H3: =H2+7 -> 43914 | I3: =I2+7 -> 43921 | J3: =J2+7 -> 43928 | K3: =K2+7 -> 43935 | ... W3: =W2+7 -> 44020
B4: Mega Region | C4: Product | D4: 2/18 to 2/25 | E4: 2/25 to 3/3 | F4: 3/3 to 3/10 | G4: 3/10 to 3/17 | H4: 3/17 to 3/24 | I4: 3/24 to 3/31 | J4: 3/31 to 4/7 | K4: 4/7 to 4/14 | L4: 4/14 to 4/21 | M4: 4/21 to 4/28 | N4: 4/28 to 5/5 | O4: 5/5 to 5/12 | P4: 5/12 to 5/19 | Q4: 5/19 to 5/26 | R4: 5/26 to 6/2 | S4: 6/2 to 6/9 | T4: 6/9 to 6/16 | U4: 6/16 to 6/23 | V4: 6/23 to 6/30 | W4: 7/1 to 7/7
B5: APACx | C5: Travel | D5: =countifs(#REF!,$B5,'Attainment Query Data'!$H:$H,$C5,'Attainment Query Data'!$G:$G,">"&D$2,'Attainment Query Data'!$G:$G,"<="&D$3) -> #VALUE! | E5: =countifs(#REF!,$B5,'Attainment Query Data'!$H:$H,$C5,'Attainment Query Data'!$G:$G,">"&E$2,'Attainment Query Data'!$G:$G,"<="&E$3) -> #VALUE! | F5: =countifs(#REF!,$B5,'Attainment Query Data'!$H:$H,$C5,'Attainment Query Data'!$G:$G,">"&F$2,'Attainment Query Data'!$G:$G,"<="&F$3) -> #VALUE! | G5: =countifs(#REF!,$B5,'Attainment Query Data'!$H:$H,$C5,'Attainment Query Data'!$G:$G,">"&G$2,'Attainment Query Data'!$G:$G,"<="&G$3) -> #VALUE! | H5: =countifs(#REF!,$B5,'Attainment Query Data'!$H:$H,$C5,'Attainment Query Data'!$G:$G,">"&H$2,'Attainment Query Data'!$G:$G,"<="&H$3) -> #VALUE! | I5: =countifs(#REF!,$B5,'Attainment Query Data'!$H:$H,$C5,'Attainment Query Data'!$G:$G,">"&I$2,'Attainment Query Data'!$G:$G,"<="&I$3) -> #VALUE! | J5: =countifs(#REF!,$B5,'Attainment Query Data'!$H:$H,$C5,'Attainment Query Data'!$G:$G,">"&J$2,'Attainment Query Data'!$G:$G,"<="&J$3) -> #VALUE! | K5: =countifs(#REF!,$B5,'Attainment Query Data'!$H:$H,$C5,'Attainment Query Data'!$G:$G,">"&K$2,'Attainment Query Data'!$G:$G,"<="&K$3) -> #VALUE! | ... W5: =countifs(#REF!,$B5,'Attainment Query Data'!$H:$H,$C5,'Attainment Query Data'!$G:$G,">"&W$2,'Attainment Query Data'!$G:$G,"<="&W$3) -> #VALUE!
B6: APACx | C6: Vouchers | D6: =countifs(#REF!,$B6,'Attainment Query Data'!$H:$H,$C6,'Attainment Query Data'!$G:$G,">"&D$2,'Attainment Query Data'!$G:$G,"<="&D$3) -> #VALUE! | E6: =countifs(#REF!,$B6,'Attainment Query Data'!$H:$H,$C6,'Attainment Query Data'!$G:$G,">"&E$2,'Attainment Query Data'!$G:$G,"<="&E$3) -> #VALUE! | F6: =countifs(#REF!,$B6,'Attainment Query Data'!$H:$H,$C6,'Attainment Query Data'!$G:$G,">"&F$2,'Attainment Query Data'!$G:$G,"<="&F$3) -> #VALUE! | G6: =countifs(#REF!,$B6,'Attainment Query Data'!$H:$H,$C6,'Attainment Query Data'!$G:$G,">"&G$2,'Attainment Query Data'!$G:$G,"<="&G$3) -> #VALUE! | H6: =countifs(#REF!,$B6,'Attainment Query Data'!$H:$H,$C6,'Attainment Query Data'!$G:$G,">"&H$2,'Attainment Query Data'!$G:$G,"<="&H$3) -> #VALUE! | I6: =countifs(#REF!,$B6,'Attainment Query Data'!$H:$H,$C6,'Attainment Query Data'!$G:$G,">"&I$2,'Attainment Query Data'!$G:$G,"<="&I$3) -> #VALUE! | J6: =countifs(#REF!,$B6,'Attainment Query Data'!$H:$H,$C6,'Attainment Query Data'!$G:$G,">"&J$2,'Attainment Query Data'!$G:$G,"<="&J$3) -> #VALUE! | K6: =countifs(#REF!,$B6,'Attainment Query Data'!$H:$H,$C6,'Attainment Query Data'!$G:$G,">"&K$2,'Attainment Query Data'!$G:$G,"<="&K$3) -> #VALUE! | ... W6: =countifs(#REF!,$B6,'Attainment Query Data'!$H:$H,$C6,'Attainment Query Data'!$G:$G,">"&W$2,'Attainment Query Data'!$G:$G,"<="&W$3) -> #VALUE!
B7: APACx | C7: E4B Vouchers | D7: =countifs(#REF!,$B7,'Attainment Query Data'!$H:$H,$C7,'Attainment Query Data'!$G:$G,">"&D$2,'Attainment Query Data'!$G:$G,"<="&D$3) -> #VALUE! | E7: =countifs(#REF!,$B7,'Attainment Query Data'!$H:$H,$C7,'Attainment Query Data'!$G:$G,">"&E$2,'Attainment Query Data'!$G:$G,"<="&E$3) -> #VALUE! | F7: =countifs(#REF!,$B7,'Attainment Query Data'!$H:$H,$C7,'Attainment Query Data'!$G:$G,">"&F$2,'Attainment Query Data'!$G:$G,"<="&F$3) -> #VALUE! | G7: =countifs(#REF!,$B7,'Attainment Query Data'!$H:$H,$C7,'Attainment Query Data'!$G:$G,">"&G$2,'Attainment Query Data'!$G:$G,"<="&G$3) -> #VALUE! | H7: =countifs(#REF!,$B7,'Attainment Query Data'!$H:$H,$C7,'Attainment Query Data'!$G:$G,">"&H$2,'Attainment Query Data'!$G:$G,"<="&H$3) -> #VALUE! | I7: =countifs(#REF!,$B7,'Attainment Query Data'!$H:$H,$C7,'Attainment Query Data'!$G:$G,">"&I$2,'Attainment Query Data'!$G:$G,"<="&I$3) -> #VALUE! | J7: =countifs(#REF!,$B7,'Attainment Query Data'!$H:$H,$C7,'Attainment Query Data'!$G:$G,">"&J$2,'Attainment Query Data'!$G:$G,"<="&J$3) -> #VALUE! | K7: =countifs(#REF!,$B7,'Attainment Query Data'!$H:$H,$C7,'Attainment Query Data'!$G:$G,">"&K$2,'Attainment Query Data'!$G:$G,"<="&K$3) -> #VALUE! | ... W7: =countifs(#REF!,$B7,'Attainment Query Data'!$H:$H,$C7,'Attainment Query Data'!$G:$G,">"&W$2,'Attainment Query Data'!$G:$G,"<="&W$3) -> #VALUE!
B8: APACx | C8: Central | D8: =countifs(#REF!,$B8,'Attainment Query Data'!$H:$H,$C8,'Attainment Query Data'!$G:$G,">"&D$2,'Attainment Query Data'!$G:$G,"<="&D$3) -> #VALUE! | E8: =countifs(#REF!,$B8,'Attainment Query Data'!$H:$H,$C8,'Attainment Query Data'!$G:$G,">"&E$2,'Attainment Query Data'!$G:$G,"<="&E$3) -> #VALUE! | F8: =countifs(#REF!,$B8,'Attainment Query Data'!$H:$H,$C8,'Attainment Query Data'!$G:$G,">"&F$2,'Attainment Query Data'!$G:$G,"<="&F$3) -> #VALUE! | G8: =countifs(#REF!,$B8,'Attainment Query Data'!$H:$H,$C8,'Attainment Query Data'!$G:$G,">"&G$2,'Attainment Query Data'!$G:$G,"<="&G$3) -> #VALUE! | H8: =countifs(#REF!,$B8,'Attainment Query Data'!$H:$H,$C8,'Attainment Query Data'!$G:$G,">"&H$2,'Attainment Query Data'!$G:$G,"<="&H$3) -> #VALUE! | I8: =countifs(#REF!,$B8,'Attainment Query Data'!$H:$H,$C8,'Attainment Query Data'!$G:$G,">"&I$2,'Attainment Query Data'!$G:$G,"<="&I$3) -> #VALUE! | J8: =countifs(#REF!,$B8,'Attainment Query Data'!$H:$H,$C8,'Attainment Query Data'!$G:$G,">"&J$2,'Attainment Query Data'!$G:$G,"<="&J$3) -> #VALUE! | K8: =countifs(#REF!,$B8,'Attainment Query Data'!$H:$H,$C8,'Attainment Query Data'!$G:$G,">"&K$2,'Attainment Query Data'!$G:$G,"<="&K$3) -> #VALUE! | ... W8: =countifs(#REF!,$B8,'Attainment Query Data'!$H:$H,$C8,'Attainment Query Data'!$G:$G,">"&W$2,'Attainment Query Data'!$G:$G,"<="&W$3) -> #VALUE!
B9: APACx | C9: Eats | D9: =countifs(#REF!,$B9,'Attainment Query Data'!$H:$H,$C9,'Attainment Query Data'!$G:$G,">"&D$2,'Attainment Query Data'!$G:$G,"<="&D$3) -> #VALUE! | E9: =countifs(#REF!,$B9,'Attainment Query Data'!$H:$H,$C9,'Attainment Query Data'!$G:$G,">"&E$2,'Attainment Query Data'!$G:$G,"<="&E$3) -> #VALUE! | F9: =countifs(#REF!,$B9,'Attainment Query Data'!$H:$H,$C9,'Attainment Query Data'!$G:$G,">"&F$2,'Attainment Query Data'!$G:$G,"<="&F$3) -> #VALUE! | G9: =countifs(#REF!,$B9,'Attainment Query Data'!$H:$H,$C9,'Attainment Query Data'!$G:$G,">"&G$2,'Attainment Query Data'!$G:$G,"<="&G$3) -> #VALUE! | H9: =countifs(#REF!,$B9,'Attainment Query Data'!$H:$H,$C9,'Attainment Query Data'!$G:$G,">"&H$2,'Attainment Query Data'!$G:$G,"<="&H$3) -> #VALUE! | I9: =countifs(#REF!,$B9,'Attainment Query Data'!$H:$H,$C9,'Attainment Query Data'!$G:$G,">"&I$2,'Attainment Query Data'!$G:$G,"<="&I$3) -> #VALUE! | J9: =countifs(#REF!,$B9,'Attainment Query Data'!$H:$H,$C9,'Attainment Query Data'!$G:$G,">"&J$2,'Attainment Query Data'!$G:$G,"<="&J$3) -> #VALUE! | K9: =countifs(#REF!,$B9,'Attainment Query Data'!$H:$H,$C9,'Attainment Query Data'!$G:$G,">"&K$2,'Attainment Query Data'!$G:$G,"<="&K$3) -> #VALUE! | ... W9: =countifs(#REF!,$B9,'Attainment Query Data'!$H:$H,$C9,'Attainment Query Data'!$G:$G,">"&W$2,'Attainment Query Data'!$G:$G,"<="&W$3) -> #VALUE!
B10: APACx | C10: Gift Card | D10: =countifs(#REF!,$B10,'Attainment Query Data'!$H:$H,$C10,'Attainment Query Data'!$G:$G,">"&D$2,'Attainment Query Data'!$G:$G,"<="&D$3) -> #VALUE! | E10: =countifs(#REF!,$B10,'Attainment Query Data'!$H:$H,$C10,'Attainment Query Data'!$G:$G,">"&E$2,'Attainment Query Data'!$G:$G,"<="&E$3) -> #VALUE! | F10: =countifs(#REF!,$B10,'Attainment Query Data'!$H:$H,$C10,'Attainment Query Data'!$G:$G,">"&F$2,'Attainment Query Data'!$G:$G,"<="&F$3) -> #VALUE! | G10: =countifs(#REF!,$B10,'Attainment Query Data'!$H:$H,$C10,'Attainment Query Data'!$G:$G,">"&G$2,'Attainment Query Data'!$G:$G,"<="&G$3) -> #VALUE! | H10: =countifs(#REF!,$B10,'Attainment Query Data'!$H:$H,$C10,'Attainment Query Data'!$G:$G,">"&H$2,'Attainment Query Data'!$G:$G,"<="&H$3) -> #VALUE! | I10: =countifs(#REF!,$B10,'Attainment Query Data'!$H:$H,$C10,'Attainment Query Data'!$G:$G,">"&I$2,'Attainment Query Data'!$G:$G,"<="&I$3) -> #VALUE! | J10: =countifs(#REF!,$B10,'Attainment Query Data'!$H:$H,$C10,'Attainment Query Data'!$G:$G,">"&J$2,'Attainment Query Data'!$G:$G,"<="&J$3) -> #VALUE! | K10: =countifs(#REF!,$B10,'Attainment Query Data'!$H:$H,$C10,'Attainment Query Data'!$G:$G,">"&K$2,'Attainment Query Data'!$G:$G,"<="&K$3) -> #VALUE! | ... W10: =countifs(#REF!,$B10,'Attainment Query Data'!$H:$H,$C10,'Attainment Query Data'!$G:$G,">"&W$2,'Attainment Query Data'!$G:$G,"<="&W$3) -> #VALUE!
C11: Total | D11: =SUM(D5:D10) -> #VALUE! | E11: =SUM(E5:E10) -> #VALUE! | F11: =SUM(F5:F10) -> #VALUE! | G11: =SUM(G5:G10) -> #VALUE! | H11: =SUM(H5:H10) -> #VALUE! | I11: =SUM(I5:I10) -> #VALUE! | J11: =SUM(J5:J10) -> #VALUE! | K11: =SUM(K5:K10) -> #VALUE! | ... W11: =SUM(W5:W10) -> #VALUE!
B13: Mega Region | C13: Product | D13: 2/18 to 2/25 | E13: 2/25 to 3/3 | F13: 3/3 to 3/10 | G13: 3/10 to 3/17 | H13: 3/17 to 3/24 | I13: 3/24 to 3/31 | J13: 3/31 to 4/7 | K13: 4/7 to 4/14 | L13: 4/14 to 4/21 | M13: 4/21 to 4/28 | N13: 4/28 to 5/5 | O13: 5/5 to 5/12 | P13: 5/12 to 5/19 | Q13: 5/19 to 5/26 | R13: 5/26 to 6/2 | S13: 6/2 to 6/9 | T13: 6/9 to 6/16 | U13: 6/16 to 6/23 | V13: 6/23 to 6/30 | W13: 7/1 to 7/7
B14: Europe | C14: Travel | D14: =countifs(#REF!,$B14,'Attainment Query Data'!$H:$H,$C14,'Attainment Query Data'!$G:$G,">"&D$2,'Attainment Query Data'!$G:$G,"<="&D$3) -> #VALUE! | E14: =countifs(#REF!,$B14,'Attainment Query Data'!$H:$H,$C14,'Attainment Query Data'!$G:$G,">"&E$2,'Attainment Query Data'!$G:$G,"<="&E$3) -> #VALUE! | F14: =countifs(#REF!,$B14,'Attainment Query Data'!$H:$H,$C14,'Attainment Query Data'!$G:$G,">"&F$2,'Attainment Query Data'!$G:$G,"<="&F$3) -> #VALUE! | G14: =countifs(#REF!,$B14,'Attainment Query Data'!$H:$H,$C14,'Attainment Query Data'!$G:$G,">"&G$2,'Attainment Query Data'!$G:$G,"<="&G$3) -> #VALUE! | H14: =countifs(#REF!,$B14,'Attainment Query Data'!$H:$H,$C14,'Attainment Query Data'!$G:$G,">"&H$2,'Attainment Query Data'!$G:$G,"<="&H$3) -> #VALUE! | I14: =countifs(#REF!,$B14,'Attainment Query Data'!$H:$H,$C14,'Attainment Query Data'!$G:$G,">"&I$2,'Attainment Query Data'!$G:$G,"<="&I$3) -> #VALUE! | J14: =countifs(#REF!,$B14,'Attainment Query Data'!$H:$H,$C14,'Attainment Query Data'!$G:$G,">"&J$2,'Attainment Query Data'!$G:$G,"<="&J$3) -> #VALUE! | K14: =countifs(#REF!,$B14,'Attainment Query Data'!$H:$H,$C14,'Attainment Query Data'!$G:$G,">"&K$2,'Attainment Query Data'!$G:$G,"<="&K$3) -> #VALUE! | ... W14: =countifs(#REF!,$B14,'Attainment Query Data'!$H:$H,$C14,'Attainment Query Data'!$G:$G,">"&W$2,'Attainment Query Data'!$G:$G,"<="&W$3) -> #VALUE!
B15: Europe | C15: Vouchers | D15: =countifs(#REF!,$B15,'Attainment Query Data'!$H:$H,$C15,'Attainment Query Data'!$G:$G,">"&D$2,'Attainment Query Data'!$G:$G,"<="&D$3) -> #VALUE! | E15: =countifs(#REF!,$B15,'Attainment Query Data'!$H:$H,$C15,'Attainment Query Data'!$G:$G,">"&E$2,'Attainment Query Data'!$G:$G,"<="&E$3) -> #VALUE! | F15: =countifs(#REF!,$B15,'Attainment Query Data'!$H:$H,$C15,'Attainment Query Data'!$G:$G,">"&F$2,'Attainment Query Data'!$G:$G,"<="&F$3) -> #VALUE! | G15: =countifs(#REF!,$B15,'Attainment Query Data'!$H:$H,$C15,'Attainment Query Data'!$G:$G,">"&G$2,'Attainment Query Data'!$G:$G,"<="&G$3) -> #VALUE! | H15: =countifs(#REF!,$B15,'Attainment Query Data'!$H:$H,$C15,'Attainment Query Data'!$G:$G,">"&H$2,'Attainment Query Data'!$G:$G,"<="&H$3) -> #VALUE! | I15: =countifs(#REF!,$B15,'Attainment Query Data'!$H:$H,$C15,'Attainment Query Data'!$G:$G,">"&I$2,'Attainment Query Data'!$G:$G,"<="&I$3) -> #VALUE! | J15: =countifs(#REF!,$B15,'Attainment Query Data'!$H:$H,$C15,'Attainment Query Data'!$G:$G,">"&J$2,'Attainment Query Data'!$G:$G,"<="&J$3) -> #VALUE! | K15: =countifs(#REF!,$B15,'Attainment Query Data'!$H:$H,$C15,'Attainment Query Data'!$G:$G,">"&K$2,'Attainment Query Data'!$G:$G,"<="&K$3) -> #VALUE! | ... W15: =countifs(#REF!,$B15,'Attainment Query Data'!$H:$H,$C15,'Attainment Query Data'!$G:$G,">"&W$2,'Attainment Query Data'!$G:$G,"<="&W$3) -> #VALUE!
B16: Europe | C16: E4B Vouchers | D16: =countifs(#REF!,$B16,'Attainment Query Data'!$H:$H,$C16,'Attainment Query Data'!$G:$G,">"&D$2,'Attainment Query Data'!$G:$G,"<="&D$3) -> #VALUE! | E16: =countifs(#REF!,$B16,'Attainment Query Data'!$H:$H,$C16,'Attainment Query Data'!$G:$G,">"&E$2,'Attainment Query Data'!$G:$G,"<="&E$3) -> #VALUE! | F16: =countifs(#REF!,$B16,'Attainment Query Data'!$H:$H,$C16,'Attainment Query Data'!$G:$G,">"&F$2,'Attainment Query Data'!$G:$G,"<="&F$3) -> #VALUE! | G16: =countifs(#REF!,$B16,'Attainment Query Data'!$H:$H,$C16,'Attainment Query Data'!$G:$G,">"&G$2,'Attainment Query Data'!$G:$G,"<="&G$3) -> #VALUE! | H16: =countifs(#REF!,$B16,'Attainment Query Data'!$H:$H,$C16,'Attainment Query Data'!$G:$G,">"&H$2,'Attainment Query Data'!$G:$G,"<="&H$3) -> #VALUE! | I16: =countifs(#REF!,$B16,'Attainment Query Data'!$H:$H,$C16,'Attainment Query Data'!$G:$G,">"&I$2,'Attainment Query Data'!$G:$G,"<="&I$3) -> #VALUE! | J16: =countifs(#REF!,$B16,'Attainment Query Data'!$H:$H,$C16,'Attainment Query Data'!$G:$G,">"&J$2,'Attainment Query Data'!$G:$G,"<="&J$3) -> #VALUE! | K16: =countifs(#REF!,$B16,'Attainment Query Data'!$H:$H,$C16,'Attainment Query Data'!$G:$G,">"&K$2,'Attainment Query Data'!$G:$G,"<="&K$3) -> #VALUE! | ... W16: =countifs(#REF!,$B16,'Attainment Query Data'!$H:$H,$C16,'Attainment Query Data'!$G:$G,">"&W$2,'Attainment Query Data'!$G:$G,"<="&W$3) -> #VALUE!
B17: Europe | C17: Central | D17: =countifs(#REF!,$B17,'Attainment Query Data'!$H:$H,$C17,'Attainment Query Data'!$G:$G,">"&D$2,'Attainment Query Data'!$G:$G,"<="&D$3) -> #VALUE! | E17: =countifs(#REF!,$B17,'Attainment Query Data'!$H:$H,$C17,'Attainment Query Data'!$G:$G,">"&E$2,'Attainment Query Data'!$G:$G,"<="&E$3) -> #VALUE! | F17: =countifs(#REF!,$B17,'Attainment Query Data'!$H:$H,$C17,'Attainment Query Data'!$G:$G,">"&F$2,'Attainment Query Data'!$G:$G,"<="&F$3) -> #VALUE! | G17: =countifs(#REF!,$B17,'Attainment Query Data'!$H:$H,$C17,'Attainment Query Data'!$G:$G,">"&G$2,'Attainment Query Data'!$G:$G,"<="&G$3) -> #VALUE! | H17: =countifs(#REF!,$B17,'Attainment Query Data'!$H:$H,$C17,'Attainment Query Data'!$G:$G,">"&H$2,'Attainment Query Data'!$G:$G,"<="&H$3) -> #VALUE! | I17: =countifs(#REF!,$B17,'Attainment Query Data'!$H:$H,$C17,'Attainment Query Data'!$G:$G,">"&I$2,'Attainment Query Data'!$G:$G,"<="&I$3) -> #VALUE! | J17: =countifs(#REF!,$B17,'Attainment Query Data'!$H:$H,$C17,'Attainment Query Data'!$G:$G,">"&J$2,'Attainment Query Data'!$G:$G,"<="&J$3) -> #VALUE! | K17: =countifs(#REF!,$B17,'Attainment Query Data'!$H:$H,$C17,'Attainment Query Data'!$G:$G,">"&K$2,'Attainment Query Data'!$G:$G,"<="&K$3) -> #VALUE! | ... W17: =countifs(#REF!,$B17,'Attainment Query Data'!$H:$H,$C17,'Attainment Query Data'!$G:$G,">"&W$2,'Attainment Query Data'!$G:$G,"<="&W$3) -> #VALUE!
B18: Europe | C18: Eats | D18: =countifs(#REF!,$B18,'Attainment Query Data'!$H:$H,$C18,'Attainment Query Data'!$G:$G,">"&D$2,'Attainment Query Data'!$G:$G,"<="&D$3) -> #VALUE! | E18: =countifs(#REF!,$B18,'Attainment Query Data'!$H:$H,$C18,'Attainment Query Data'!$G:$G,">"&E$2,'Attainment Query Data'!$G:$G,"<="&E$3) -> #VALUE! | F18: =countifs(#REF!,$B18,'Attainment Query Data'!$H:$H,$C18,'Attainment Query Data'!$G:$G,">"&F$2,'Attainment Query Data'!$G:$G,"<="&F$3) -> #VALUE! | G18: =countifs(#REF!,$B18,'Attainment Query Data'!$H:$H,$C18,'Attainment Query Data'!$G:$G,">"&G$2,'Attainment Query Data'!$G:$G,"<="&G$3) -> #VALUE! | H18: =countifs(#REF!,$B18,'Attainment Query Data'!$H:$H,$C18,'Attainment Query Data'!$G:$G,">"&H$2,'Attainment Query Data'!$G:$G,"<="&H$3) -> #VALUE! | I18: =countifs(#REF!,$B18,'Attainment Query Data'!$H:$H,$C18,'Attainment Query Data'!$G:$G,">"&I$2,'Attainment Query Data'!$G:$G,"<="&I$3) -> #VALUE! | J18: =countifs(#REF!,$B18,'Attainment Query Data'!$H:$H,$C18,'Attainment Query Data'!$G:$G,">"&J$2,'Attainment Query Data'!$G:$G,"<="&J$3) -> #VALUE! | K18: =countifs(#REF!,$B18,'Attainment Query Data'!$H:$H,$C18,'Attainment Query Data'!$G:$G,">"&K$2,'Attainment Query Data'!$G:$G,"<="&K$3) -> #VALUE! | ... W18: =countifs(#REF!,$B18,'Attainment Query Data'!$H:$H,$C18,'Attainment Query Data'!$G:$G,">"&W$2,'Attainment Query Data'!$G:$G,"<="&W$3) -> #VALUE!
B19: Europe | C19: Gift Card | D19: =countifs(#REF!,$B19,'Attainment Query Data'!$H:$H,$C19,'Attainment Query Data'!$G:$G,">"&D$2,'Attainment Query Data'!$G:$G,"<="&D$3) -> #VALUE! | E19: =countifs(#REF!,$B19,'Attainment Query Data'!$H:$H,$C19,'Attainment Query Data'!$G:$G,">"&E$2,'Attainment Query Data'!$G:$G,"<="&E$3) -> #VALUE! | F19: =countifs(#REF!,$B19,'Attainment Query Data'!$H:$H,$C19,'Attainment Query Data'!$G:$G,">"&F$2,'Attainment Query Data'!$G:$G,"<="&F$3) -> #VALUE! | G19: =countifs(#REF!,$B19,'Attainment Query Data'!$H:$H,$C19,'Attainment Query Data'!$G:$G,">"&G$2,'Attainment Query Data'!$G:$G,"<="&G$3) -> #VALUE! | H19: =countifs(#REF!,$B19,'Attainment Query Data'!$H:$H,$C19,'Attainment Query Data'!$G:$G,">"&H$2,'Attainment Query Data'!$G:$G,"<="&H$3) -> #VALUE! | I19: =countifs(#REF!,$B19,'Attainment Query Data'!$H:$H,$C19,'Attainment Query Data'!$G:$G,">"&I$2,'Attainment Query Data'!$G:$G,"<="&I$3) -> #VALUE! | J19: =countifs(#REF!,$B19,'Attainment Query Data'!$H:$H,$C19,'Attainment Query Data'!$G:$G,">"&J$2,'Attainment Query Data'!$G:$G,"<="&J$3) -> #VALUE! | K19: =countifs(#REF!,$B19,'Attainment Query Data'!$H:$H,$C19,'Attainment Query Data'!$G:$G,">"&K$2,'Attainment Query Data'!$G:$G,"<="&K$3) -> #VALUE! | ... W19: =countifs(#REF!,$B19,'Attainment Query Data'!$H:$H,$C19,'Attainment Query Data'!$G:$G,">"&W$2,'Attainment Query Data'!$G:$G,"<="&W$3) -> #VALUE!
C20: Total | D20: =SUM(D14:D19) -> #VALUE! | E20: =SUM(E14:E19) -> #VALUE! | F20: =SUM(F14:F19) -> #VALUE! | G20: =SUM(G14:G19) -> #VALUE! | H20: =SUM(H14:H19) -> #VALUE! | I20: =SUM(I14:I19) -> #VALUE! | J20: =SUM(J14:J19) -> #VALUE! | K20: =SUM(K14:K19) -> #VALUE! | ... W20: =SUM(W14:W19) -> #VALUE!
B22: Mega Region | C22: Product | D22: 2/18 to 2/25 | E22: 2/25 to 3/3 | F22: 3/3 to 3/10 | G22: 3/10 to 3/17 | H22: 3/17 to 3/24 | I22: 3/24 to 3/31 | J22: 3/31 to 4/7 | K22: 4/7 to 4/14 | L22: 4/14 to 4/21 | M22: 4/21 to 4/28 | N22: 4/28 to 5/5 | O22: 5/5 to 5/12 | P22: 5/12 to 5/19 | Q22: 5/19 to 5/26 | R22: 5/26 to 6/2 | S22: 6/2 to 6/9 | T22: 6/9 to 6/16 | U22: 6/16 to 6/23 | V22: 6/23 to 6/30 | W22: 7/1 to 7/7
B23: MEA | C23: Travel | D23: =countifs(#REF!,$B23,'Attainment Query Data'!$H:$H,$C23,'Attainment Query Data'!$G:$G,">"&D$2,'Attainment Query Data'!$G:$G,"<="&D$3) -> #VALUE! | E23: =countifs(#REF!,$B23,'Attainment Query Data'!$H:$H,$C23,'Attainment Query Data'!$G:$G,">"&E$2,'Attainment Query Data'!$G:$G,"<="&E$3) -> #VALUE! | F23: =countifs(#REF!,$B23,'Attainment Query Data'!$H:$H,$C23,'Attainment Query Data'!$G:$G,">"&F$2,'Attainment Query Data'!$G:$G,"<="&F$3) -> #VALUE! | G23: =countifs(#REF!,$B23,'Attainment Query Data'!$H:$H,$C23,'Attainment Query Data'!$G:$G,">"&G$2,'Attainment Query Data'!$G:$G,"<="&G$3) -> #VALUE! | H23: =countifs(#REF!,$B23,'Attainment Query Data'!$H:$H,$C23,'Attainment Query Data'!$G:$G,">"&H$2,'Attainment Query Data'!$G:$G,"<="&H$3) -> #VALUE! | I23: =countifs(#REF!,$B23,'Attainment Query Data'!$H:$H,$C23,'Attainment Query Data'!$G:$G,">"&I$2,'Attainment Query Data'!$G:$G,"<="&I$3) -> #VALUE! | J23: =countifs(#REF!,$B23,'Attainment Query Data'!$H:$H,$C23,'Attainment Query Data'!$G:$G,">"&J$2,'Attainment Query Data'!$G:$G,"<="&J$3) -> #VALUE! | K23: =countifs(#REF!,$B23,'Attainment Query Data'!$H:$H,$C23,'Attainment Query Data'!$G:$G,">"&K$2,'Attainment Query Data'!$G:$G,"<="&K$3) -> #VALUE! | ... W23: =countifs(#REF!,$B23,'Attainment Query Data'!$H:$H,$C23,'Attainment Query Data'!$G:$G,">"&W$2,'Attainment Query Data'!$G:$G,"<="&W$3) -> #VALUE!
B24: MEA | C24: Vouchers | D24: =countifs(#REF!,$B24,'Attainment Query Data'!$H:$H,$C24,'Attainment Query Data'!$G:$G,">"&D$2,'Attainment Query Data'!$G:$G,"<="&D$3) -> #VALUE! | E24: =countifs(#REF!,$B24,'Attainment Query Data'!$H:$H,$C24,'Attainment Query Data'!$G:$G,">"&E$2,'Attainment Query Data'!$G:$G,"<="&E$3) -> #VALUE! | F24: =countifs(#REF!,$B24,'Attainment Query Data'!$H:$H,$C24,'Attainment Query Data'!$G:$G,">"&F$2,'Attainment Query Data'!$G:$G,"<="&F$3) -> #VALUE! | G24: =countifs(#REF!,$B24,'Attainment Query Data'!$H:$H,$C24,'Attainment Query Data'!$G:$G,">"&G$2,'Attainment Query Data'!$G:$G,"<="&G$3) -> #VALUE! | H24: =countifs(#REF!,$B24,'Attainment Query Data'!$H:$H,$C24,'Attainment Query Data'!$G:$G,">"&H$2,'Attainment Query Data'!$G:$G,"<="&H$3) -> #VALUE! | I24: =countifs(#REF!,$B24,'Attainment Query Data'!$H:$H,$C24,'Attainment Query Data'!$G:$G,">"&I$2,'Attainment Query Data'!$G:$G,"<="&I$3) -> #VALUE! | J24: =countifs(#REF!,$B24,'Attainment Query Data'!$H:$H,$C24,'Attainment Query Data'!$G:$G,">"&J$2,'Attainment Query Data'!$G:$G,"<="&J$3) -> #VALUE! | K24: =countifs(#REF!,$B24,'Attainment Query Data'!$H:$H,$C24,'Attainment Query Data'!$G:$G,">"&K$2,'Attainment Query Data'!$G:$G,"<="&K$3) -> #VALUE! | ... W24: =countifs(#REF!,$B24,'Attainment Query Data'!$H:$H,$C24,'Attainment Query Data'!$G:$G,">"&W$2,'Attainment Query Data'!$G:$G,"<="&W$3) -> #VALUE!
B25: MEA | C25: E4B Vouchers | D25: =countifs(#REF!,$B25,'Attainment Query Data'!$H:$H,$C25,'Attainment Query Data'!$G:$G,">"&D$2,'Attainment Query Data'!$G:$G,"<="&D$3) -> #VALUE! | E25: =countifs(#REF!,$B25,'Attainment Query Data'!$H:$H,$C25,'Attainment Query Data'!$G:$G,">"&E$2,'Attainment Query Data'!$G:$G,"<="&E$3) -> #VALUE! | F25: =countifs(#REF!,$B25,'Attainment Query Data'!$H:$H,$C25,'Attainment Query Data'!$G:$G,">"&F$2,'Attainment Query Data'!$G:$G,"<="&F$3) -> #VALUE! | G25: =countifs(#REF!,$B25,'Attainment Query Data'!$H:$H,$C25,'Attainment Query Data'!$G:$G,">"&G$2,'Attainment Query Data'!$G:$G,"<="&G$3) -> #VALUE! | H25: =countifs(#REF!,$B25,'Attainment Query Data'!$H:$H,$C25,'Attainment Query Data'!$G:$G,">"&H$2,'Attainment Query Data'!$G:$G,"<="&H$3) -> #VALUE! | I25: =countifs(#REF!,$B25,'Attainment Query Data'!$H:$H,$C25,'Attainment Query Data'!$G:$G,">"&I$2,'Attainment Query Data'!$G:$G,"<="&I$3) -> #VALUE! | J25: =countifs(#REF!,$B25,'Attainment Query Data'!$H:$H,$C25,'Attainment Query Data'!$G:$G,">"&J$2,'Attainment Query Data'!$G:$G,"<="&J$3) -> #VALUE! | K25: =countifs(#REF!,$B25,'Attainment Query Data'!$H:$H,$C25,'Attainment Query Data'!$G:$G,">"&K$2,'Attainment Query Data'!$G:$G,"<="&K$3) -> #VALUE! | ... W25: =countifs(#REF!,$B25,'Attainment Query Data'!$H:$H,$C25,'Attainment Query Data'!$G:$G,">"&W$2,'Attainment Query Data'!$G:$G,"<="&W$3) -> #VALUE!
B26: MEA | C26: Central | D26: =countifs(#REF!,$B26,'Attainment Query Data'!$H:$H,$C26,'Attainment Query Data'!$G:$G,">"&D$2,'Attainment Query Data'!$G:$G,"<="&D$3) -> #VALUE! | E26: =countifs(#REF!,$B26,'Attainment Query Data'!$H:$H,$C26,'Attainment Query Data'!$G:$G,">"&E$2,'Attainment Query Data'!$G:$G,"<="&E$3) -> #VALUE! | F26: =countifs(#REF!,$B26,'Attainment Query Data'!$H:$H,$C26,'Attainment Query Data'!$G:$G,">"&F$2,'Attainment Query Data'!$G:$G,"<="&F$3) -> #VALUE! | G26: =countifs(#REF!,$B26,'Attainment Query Data'!$H:$H,$C26,'Attainment Query Data'!$G:$G,">"&G$2,'Attainment Query Data'!$G:$G,"<="&G$3) -> #VALUE! | H26: =countifs(#REF!,$B26,'Attainment Query Data'!$H:$H,$C26,'Attainment Query Data'!$G:$G,">"&H$2,'Attainment Query Data'!$G:$G,"<="&H$3) -> #VALUE! | I26: =countifs(#REF!,$B26,'Attainment Query Data'!$H:$H,$C26,'Attainment Query Data'!$G:$G,">"&I$2,'Attainment Query Data'!$G:$G,"<="&I$3) -> #VALUE! | J26: =countifs(#REF!,$B26,'Attainment Query Data'!$H:$H,$C26,'Attainment Query Data'!$G:$G,">"&J$2,'Attainment Query Data'!$G:$G,"<="&J$3) -> #VALUE! | K26: =countifs(#REF!,$B26,'Attainment Query Data'!$H:$H,$C26,'Attainment Query Data'!$G:$G,">"&K$2,'Attainment Query Data'!$G:$G,"<="&K$3) -> #VALUE! | ... W26: =countifs(#REF!,$B26,'Attainment Query Data'!$H:$H,$C26,'Attainment Query Data'!$G:$G,">"&W$2,'Attainment Query Data'!$G:$G,"<="&W$3) -> #VALUE!
B27: MEA | C27: Eats | D27: =countifs(#REF!,$B27,'Attainment Query Data'!$H:$H,$C27,'Attainment Query Data'!$G:$G,">"&D$2,'Attainment Query Data'!$G:$G,"<="&D$3) -> #VALUE! | E27: =countifs(#REF!,$B27,'Attainment Query Data'!$H:$H,$C27,'Attainment Query Data'!$G:$G,">"&E$2,'Attainment Query Data'!$G:$G,"<="&E$3) -> #VALUE! | F27: =countifs(#REF!,$B27,'Attainment Query Data'!$H:$H,$C27,'Attainment Query Data'!$G:$G,">"&F$2,'Attainment Query Data'!$G:$G,"<="&F$3) -> #VALUE! | G27: =countifs(#REF!,$B27,'Attainment Query Data'!$H:$H,$C27,'Attainment Query Data'!$G:$G,">"&G$2,'Attainment Query Data'!$G:$G,"<="&G$3) -> #VALUE! | H27: =countifs(#REF!,$B27,'Attainment Query Data'!$H:$H,$C27,'Attainment Query Data'!$G:$G,">"&H$2,'Attainment Query Data'!$G:$G,"<="&H$3) -> #VALUE! | I27: =countifs(#REF!,$B27,'Attainment Query Data'!$H:$H,$C27,'Attainment Query Data'!$G:$G,">"&I$2,'Attainment Query Data'!$G:$G,"<="&I$3) -> #VALUE! | J27: =countifs(#REF!,$B27,'Attainment Query Data'!$H:$H,$C27,'Attainment Query Data'!$G:$G,">"&J$2,'Attainment Query Data'!$G:$G,"<="&J$3) -> #VALUE! | K27: =countifs(#REF!,$B27,'Attainment Query Data'!$H:$H,$C27,'Attainment Query Data'!$G:$G,">"&K$2,'Attainment Query Data'!$G:$G,"<="&K$3) -> #VALUE! | ... W27: =countifs(#REF!,$B27,'Attainment Query Data'!$H:$H,$C27,'Attainment Query Data'!$G:$G,">"&W$2,'Attainment Query Data'!$G:$G,"<="&W$3) -> #VALUE!
B28: MEA | C28: Gift Card | D28: =countifs(#REF!,$B28,'Attainment Query Data'!$H:$H,$C28,'Attainment Query Data'!$G:$G,">"&D$2,'Attainment Query Data'!$G:$G,"<="&D$3) -> #VALUE! | E28: =countifs(#REF!,$B28,'Attainment Query Data'!$H:$H,$C28,'Attainment Query Data'!$G:$G,">"&E$2,'Attainment Query Data'!$G:$G,"<="&E$3) -> #VALUE! | F28: =countifs(#REF!,$B28,'Attainment Query Data'!$H:$H,$C28,'Attainment Query Data'!$G:$G,">"&F$2,'Attainment Query Data'!$G:$G,"<="&F$3) -> #VALUE! | G28: =countifs(#REF!,$B28,'Attainment Query Data'!$H:$H,$C28,'Attainment Query Data'!$G:$G,">"&G$2,'Attainment Query Data'!$G:$G,"<="&G$3) -> #VALUE! | H28: =countifs(#REF!,$B28,'Attainment Query Data'!$H:$H,$C28,'Attainment Query Data'!$G:$G,">"&H$2,'Attainment Query Data'!$G:$G,"<="&H$3) -> #VALUE! | I28: =countifs(#REF!,$B28,'Attainment Query Data'!$H:$H,$C28,'Attainment Query Data'!$G:$G,">"&I$2,'Attainment Query Data'!$G:$G,"<="&I$3) -> #VALUE! | J28: =countifs(#REF!,$B28,'Attainment Query Data'!$H:$H,$C28,'Attainment Query Data'!$G:$G,">"&J$2,'Attainment Query Data'!$G:$G,"<="&J$3) -> #VALUE! | K28: =countifs(#REF!,$B28,'Attainment Query Data'!$H:$H,$C28,'Attainment Query Data'!$G:$G,">"&K$2,'Attainment Query Data'!$G:$G,"<="&K$3) -> #VALUE! | ... W28: =countifs(#REF!,$B28,'Attainment Query Data'!$H:$H,$C28,'Attainment Query Data'!$G:$G,">"&W$2,'Attainment Query Data'!$G:$G,"<="&W$3) -> #VALUE!
C29: Total | D29: =SUM(D23:D28) -> #VALUE! | E29: =SUM(E23:E28) -> #VALUE! | F29: =SUM(F23:F28) -> #VALUE! | G29: =SUM(G23:G28) -> #VALUE! | H29: =SUM(H23:H28) -> #VALUE! | I29: =SUM(I23:I28) -> #VALUE! | J29: =SUM(J23:J28) -> #VALUE! | K29: =SUM(K23:K28) -> #VALUE! | ... W29: =SUM(W23:W28) -> #VALUE!
B31: , | C31: Product | D31: 2/18 to 2/25 | E31: 2/25 to 3/3 | F31: 3/3 to 3/10 | G31: 3/10 to 3/17 | H31: 3/17 to 3/24 | I31: 3/24 to 3/31 | J31: 3/31 to 4/7 | K31: 4/7 to 4/14 | L31: 4/14 to 4/21 | M31: 4/21 to 4/28 | N31: 4/28 to 5/5 | O31: 5/5 to 5/12 | P31: 5/12 to 5/19 | Q31: 5/19 to 5/26 | R31: 5/26 to 6/2 | S31: 6/2 to 6/9 | T31: 6/9 to 6/16 | U31: 6/16 to 6/23 | V31: 6/23 to 6/30 | W31: 7/1 to 7/7
B32: India | C32: Travel | D32: =countifs(#REF!,$B32,'Attainment Query Data'!$H:$H,$C32,'Attainment Query Data'!$G:$G,">"&D$2,'Attainment Query Data'!$G:$G,"<="&D$3) -> #VALUE! | E32: =countifs(#REF!,$B32,'Attainment Query Data'!$H:$H,$C32,'Attainment Query Data'!$G:$G,">"&E$2,'Attainment Query Data'!$G:$G,"<="&E$3) -> #VALUE! | F32: =countifs(#REF!,$B32,'Attainment Query Data'!$H:$H,$C32,'Attainment Query Data'!$G:$G,">"&F$2,'Attainment Query Data'!$G:$G,"<="&F$3) -> #VALUE! | G32: =countifs(#REF!,$B32,'Attainment Query Data'!$H:$H,$C32,'Attainment Query Data'!$G:$G,">"&G$2,'Attainment Query Data'!$G:$G,"<="&G$3) -> #VALUE! | H32: =countifs(#REF!,$B32,'Attainment Query Data'!$H:$H,$C32,'Attainment Query Data'!$G:$G,">"&H$2,'Attainment Query Data'!$G:$G,"<="&H$3) -> #VALUE! | I32: =countifs(#REF!,$B32,'Attainment Query Data'!$H:$H,$C32,'Attainment Query Data'!$G:$G,">"&I$2,'Attainment Query Data'!$G:$G,"<="&I$3) -> #VALUE! | J32: =countifs(#REF!,$B32,'Attainment Query Data'!$H:$H,$C32,'Attainment Query Data'!$G:$G,">"&J$2,'Attainment Query Data'!$G:$G,"<="&J$3) -> #VALUE! | K32: =countifs(#REF!,$B32,'Attainment Query Data'!$H:$H,$C32,'Attainment Query Data'!$G:$G,">"&K$2,'Attainment Query Data'!$G:$G,"<="&K$3) -> #VALUE! | ... W32: =countifs(#REF!,$B32,'Attainment Query Data'!$H:$H,$C32,'Attainment Query Data'!$G:$G,">"&W$2,'Attainment Query Data'!$G:$G,"<="&W$3) -> #VALUE!
B33: India | C33: Vouchers | D33: =countifs(#REF!,$B33,'Attainment Query Data'!$H:$H,$C33,'Attainment Query Data'!$G:$G,">"&D$2,'Attainment Query Data'!$G:$G,"<="&D$3) -> #VALUE! | E33: =countifs(#REF!,$B33,'Attainment Query Data'!$H:$H,$C33,'Attainment Query Data'!$G:$G,">"&E$2,'Attainment Query Data'!$G:$G,"<="&E$3) -> #VALUE! | F33: =countifs(#REF!,$B33,'Attainment Query Data'!$H:$H,$C33,'Attainment Query Data'!$G:$G,">"&F$2,'Attainment Query Data'!$G:$G,"<="&F$3) -> #VALUE! | G33: =countifs(#REF!,$B33,'Attainment Query Data'!$H:$H,$C33,'Attainment Query Data'!$G:$G,">"&G$2,'Attainment Query Data'!$G:$G,"<="&G$3) -> #VALUE! | H33: =countifs(#REF!,$B33,'Attainment Query Data'!$H:$H,$C33,'Attainment Query Data'!$G:$G,">"&H$2,'Attainment Query Data'!$G:$G,"<="&H$3) -> #VALUE! | I33: =countifs(#REF!,$B33,'Attainment Query Data'!$H:$H,$C33,'Attainment Query Data'!$G:$G,">"&I$2,'Attainment Query Data'!$G:$G,"<="&I$3) -> #VALUE! | J33: =countifs(#REF!,$B33,'Attainment Query Data'!$H:$H,$C33,'Attainment Query Data'!$G:$G,">"&J$2,'Attainment Query Data'!$G:$G,"<="&J$3) -> #VALUE! | K33: =countifs(#REF!,$B33,'Attainment Query Data'!$H:$H,$C33,'Attainment Query Data'!$G:$G,">"&K$2,'Attainment Query Data'!$G:$G,"<="&K$3) -> #VALUE! | ... W33: =countifs(#REF!,$B33,'Attainment Query Data'!$H:$H,$C33,'Attainment Query Data'!$G:$G,">"&W$2,'Attainment Query Data'!$G:$G,"<="&W$3) -> #VALUE!
B34: India | C34: E4B Vouchers | D34: =countifs(#REF!,$B34,'Attainment Query Data'!$H:$H,$C34,'Attainment Query Data'!$G:$G,">"&D$2,'Attainment Query Data'!$G:$G,"<="&D$3) -> #VALUE! | E34: =countifs(#REF!,$B34,'Attainment Query Data'!$H:$H,$C34,'Attainment Query Data'!$G:$G,">"&E$2,'Attainment Query Data'!$G:$G,"<="&E$3) -> #VALUE! | F34: =countifs(#REF!,$B34,'Attainment Query Data'!$H:$H,$C34,'Attainment Query Data'!$G:$G,">"&F$2,'Attainment Query Data'!$G:$G,"<="&F$3) -> #VALUE! | G34: =countifs(#REF!,$B34,'Attainment Query Data'!$H:$H,$C34,'Attainment Query Data'!$G:$G,">"&G$2,'Attainment Query Data'!$G:$G,"<="&G$3) -> #VALUE! | H34: =countifs(#REF!,$B34,'Attainment Query Data'!$H:$H,$C34,'Attainment Query Data'!$G:$G,">"&H$2,'Attainment Query Data'!$G:$G,"<="&H$3) -> #VALUE! | I34: =countifs(#REF!,$B34,'Attainment Query Data'!$H:$H,$C34,'Attainment Query Data'!$G:$G,">"&I$2,'Attainment Query Data'!$G:$G,"<="&I$3) -> #VALUE! | J34: =countifs(#REF!,$B34,'Attainment Query Data'!$H:$H,$C34,'Attainment Query Data'!$G:$G,">"&J$2,'Attainment Query Data'!$G:$G,"<="&J$3) -> #VALUE! | K34: =countifs(#REF!,$B34,'Attainment Query Data'!$H:$H,$C34,'Attainment Query Data'!$G:$G,">"&K$2,'Attainment Query Data'!$G:$G,"<="&K$3) -> #VALUE! | ... W34: =countifs(#REF!,$B34,'Attainment Query Data'!$H:$H,$C34,'Attainment Query Data'!$G:$G,">"&W$2,'Attainment Query Data'!$G:$G,"<="&W$3) -> #VALUE!
B35: India | C35: Central | D35: =countifs(#REF!,$B35,'Attainment Query Data'!$H:$H,$C35,'Attainment Query Data'!$G:$G,">"&D$2,'Attainment Query Data'!$G:$G,"<="&D$3) -> #VALUE! | E35: =countifs(#REF!,$B35,'Attainment Query Data'!$H:$H,$C35,'Attainment Query Data'!$G:$G,">"&E$2,'Attainment Query Data'!$G:$G,"<="&E$3) -> #VALUE! | F35: =countifs(#REF!,$B35,'Attainment Query Data'!$H:$H,$C35,'Attainment Query Data'!$G:$G,">"&F$2,'Attainment Query Data'!$G:$G,"<="&F$3) -> #VALUE! | G35: =countifs(#REF!,$B35,'Attainment Query Data'!$H:$H,$C35,'Attainment Query Data'!$G:$G,">"&G$2,'Attainment Query Data'!$G:$G,"<="&G$3) -> #VALUE! | H35: =countifs(#REF!,$B35,'Attainment Query Data'!$H:$H,$C35,'Attainment Query Data'!$G:$G,">"&H$2,'Attainment Query Data'!$G:$G,"<="&H$3) -> #VALUE! | I35: =countifs(#REF!,$B35,'Attainment Query Data'!$H:$H,$C35,'Attainment Query Data'!$G:$G,">"&I$2,'Attainment Query Data'!$G:$G,"<="&I$3) -> #VALUE! | J35: =countifs(#REF!,$B35,'Attainment Query Data'!$H:$H,$C35,'Attainment Query Data'!$G:$G,">"&J$2,'Attainment Query Data'!$G:$G,"<="&J$3) -> #VALUE! | K35: =countifs(#REF!,$B35,'Attainment Query Data'!$H:$H,$C35,'Attainment Query Data'!$G:$G,">"&K$2,'Attainment Query Data'!$G:$G,"<="&K$3) -> #VALUE! | ... W35: =countifs(#REF!,$B35,'Attainment Query Data'!$H:$H,$C35,'Attainment Query Data'!$G:$G,">"&W$2,'Attainment Query Data'!$G:$G,"<="&W$3) -> #VALUE!
